<mujoco model="mujoco_panda_model">

    <compiler angle="radian"/>

    <asset>
        <mesh name="link0_collision" file="meshes/collision/link0.stl"/>
        <mesh name="link1_collision" file="meshes/collision/link1.stl"/>
        <mesh name="link2_collision" file="meshes/collision/link2.stl"/>
        <mesh name="link3_collision" file="meshes/collision/link3.stl"/>
        <mesh name="link4_collision" file="meshes/collision/link4.stl"/>
        <mesh name="link5_collision" file="meshes/collision/link5.stl"/>
        <mesh name="link6_collision" file="meshes/collision/link6.stl"/>
        <mesh name="link7_collision" file="meshes/collision/link7.stl"/>
        <mesh name="hand_collision" file="meshes/collision/hand.stl"/>
        <mesh name="finger_collision" file="meshes/collision/finger.stl" scale='1.75 1.0 1.75'/>
<!--         <mesh name="bottle_collision" file="../cup/mug_cup.stl" scale='0.15 0.5 0.15'/> -->
        <mesh name="link0_visual" file="meshes/visual/link0.stl"/>
        <mesh name="link1_visual" file="meshes/visual/link1.stl"/>
        <mesh name="link2_visual" file="meshes/visual/link2.stl"/>
        <mesh name="link3_visual" file="meshes/visual/link3.stl"/>
        <mesh name="link4_visual" file="meshes/visual/link4.stl"/>
        <mesh name="link5_visual" file="meshes/visual/link5.stl"/>
        <mesh name="link6_visual" file="meshes/visual/link6.stl"/>
        <mesh name="link7_visual" file="meshes/visual/link7.stl"/>
        <mesh name="hand_visual" file="meshes/visual/hand.stl"/>
        <mesh name="finger_visual" file="meshes/visual/finger.stl" scale='1.75 1.0 1.75'/>
<!--         <mesh name="bottle_visual" file="../cup/mug_cup.stl" scale='0.15 0.5 0.15'/> -->
    </asset>
    <default>
        <default class="panda">
            <joint pos="0 0 0" axis="0 0 1" limited="true" damping="100"/>
            <position forcelimited="true" ctrllimited="true" user="1002 40 2001 -0.005 0.005"/>
            <default class="visual">
                <geom contype="0" conaffinity="0" group="0" type="mesh" rgba=".95 .99 .92 1" mass="0"/>
            </default>

            <default class="collision">
                <geom contype="1" conaffinity="1" group="3" type="mesh" rgba=".5 .6 .7 1"/>
            </default>
             <default class="panda_finger">
                <joint damping="100" armature='5'/>
            </default>
        </default>
    </default>
    
    <compiler meshdir=""/>

    <option cone="elliptic">
        <flag gravity="disable"/>
    </option>

    <worldbody>
        <body name="panda_link0" childclass="panda" >
            <inertial pos="0 0 0" quat="1 0 0 0" mass="3.06" diaginertia="0.3 0.3 0.3" />
            <geom class="visual" mesh="link0_visual"/>
            <!-- <geom class="collision" mesh="link0_collision"/> -->

            <body name="panda_link1" pos="0 0 0.333">
                <inertial pos="3.875e-03 2.081e-03 -0.1750" quat="1 0 0 0" mass="2.36" diaginertia="0.0085 0.7034 0.7071" />
                <joint name="panda_joint1" range="-2.8973 2.8973"/>
                <geom class="visual" mesh="link1_visual"/>
                <geom class="collision" mesh="link1_collision"/>

                <body name="panda_link2" pos="0 0 0" quat="0.707107 -0.707107 0 0">
                    <inertial pos="-3.141e-03 -2.872e-02 3.495e-03" quat="1 0 0 0" mass="2.38" diaginertia="0.0027 0.0310 0.0283" />
                    <joint name="panda_joint2" range="-1.7628 1.7628"/>
                    <geom class="visual" mesh="link2_visual"/>
                    <geom class="collision" mesh="link2_collision"/>

                    <body name="panda_link3" pos="0 -0.316 0" quat="0.707107 0.707107 0 0">
                        <inertial pos="2.7518e-02 3.9252e-02 -6.6502e-02" quat="1 0 0 0" mass="2.65" diaginertia="0.0012 0.0415 0.0415" />
                        <joint name="panda_joint3" range="-2.8973 2.8973"/>
                        <geom class="visual" mesh="link3_visual"/>
                        <geom class="collision" mesh="link3_collision"/>

                        <body name="panda_link4" pos="0.0825 0 0" quat="0.707107 0.707107 0 0">
                            <inertial pos="-5.317e-02 1.04419e-01 2.7454e-02" quat="1 0 0 0" mass="2.695" diaginertia="0.0106 0.0281 0.0350" />
                            <joint name="panda_joint4" range="-3.0718 -0.0698"/>
                            <geom class="visual" mesh="link4_visual"/>
                            <geom class="collision" mesh="link4_collision"/>

                            <body name="panda_link5" pos="-0.0825 0.384 0" quat="0.707107 -0.707107 0 0">
                                <inertial pos="-1.1953e-02 4.1065e-02 -3.8437e-02" quat="1 0 0 0" mass="2.98" diaginertia="0.0080 0.0368 0.0289" />
                                <joint name="panda_joint5" range="-2.8973 2.8973"/>
                                <geom class="visual" mesh="link5_visual"/>
                                <geom class="collision" mesh="link5_collision"/>

                                <body name="panda_link6" pos="0 0 0" quat="0.707107 0.707107 0 0">
                                    <inertial pos="6.0149e-02 -1.4117e-02 -1.0517e-02" quat="1 0 0 0" mass="1.13" diaginertia="0.0016 0.0058 0.0043" />
                                    <joint name="panda_joint6" range="-0.0175 3.7525"/>
                                    <geom class="visual" mesh="link6_visual"/>
                                    <geom class="collision" mesh="link6_collision"/>

                                    <body name="panda_link7" pos="0.088 0 0" quat='0.707107 0.707107 0 0'>
                                        <inertial pos="1.0517e-02 -4.252e-03 6.1597e-02" quat="1 0 0 0" mass="0.405" diaginertia="0.0045 0.0127 0.0101" />
                                        <joint name="panda_joint7" range="-1.511 2.8973"/>
                                        <geom class="visual" mesh="link7_visual"/>
                                        <geom class="collision" mesh="link7_collision"/>

                                        <site name='ee_site' pos='0 0 0.207' size="0.005, 0.005, 0.005" quat='0.9239557 0.0 0.0 -0.3824995' rgba='0 0 0 0'/>
                                        <body name="panda_hand" pos="0 0 0.107" quat='0.9239557 0.0 0.0 -0.3824995'>
                                            <inertial pos="0 0 0" euler="0 0 0" mass="0.001" diaginertia="0.0001 0.0001 0.0001" />
                                            <geom class="visual" mesh="hand_visual"/>
                                            <geom class="collision" mesh="hand_collision"/>

                                            <body name="panda_leftfinger" pos="0 0 0.0584" quat="1 0 0 0">
                                                <joint name="panda_finger_joint1"  axis="0 1 0" type="slide" range="0 0.04" damping="100" armature='5'/>
                                                <geom class="visual" mesh="finger_visual"/>
                                                <geom class="collision" mesh="finger_collision" mass="0.001"/>
                                            </body>

                                            <body name="panda_rightfinger" pos="0 0 0.0584" quat="1 0 0 0">
                                                <joint name="panda_finger_joint2" axis="0 -1 0" type="slide" range="0 0.04" damping="100" armature='5'/>
                                                <geom quat="0 0 0 1" class="visual" mesh="finger_visual"/>
                                                <geom quat="0 0 0 1" class="collision" mesh="finger_collision" mass="0.001"/>
                                            </body>
                                            
                                        </body>
                                    </body>
                                </body>
                            </body>
                        </body>
                    </body>
                </body>
            </body>
        </body>

    </worldbody>

    <actuator>
        <position name="pos_1" joint="panda_joint1" class="panda" forcerange="-87 87" ctrlrange="-2.8973 2.8973" kp="1000"/> 
        <position name="pos_2" joint="panda_joint2" class="panda" forcerange="-87 87" ctrlrange="-1.7628 1.7628" kp="1000" /> 
        <position name="pos_3" joint="panda_joint3" class="panda" forcerange="-87 87" ctrlrange="-2.8973 2.8973" kp="1000" /> 
        <position name="pos_4" joint="panda_joint4" class="panda" forcerange="-87 87" ctrlrange="-3.0718 -0.4" kp="1000" /> 
        <position name="pos_5" joint="panda_joint5" class="panda" forcerange="-12 12" ctrlrange="-2.8973 2.8973" kp="1000" /> 
        <position name="pos_6" joint="panda_joint6" class="panda" forcerange="-12 12" ctrlrange="-1.6573 2.1127" kp="500" /> 
        <position name="pos_7" joint="panda_joint7" class="panda" forcerange="-12 12" ctrlrange="-2.8973 2.8973" kp="300" /> 
        <!-- <motor name="torque_1" joint="panda_joint1" class="panda" forcerange="-87 87" ctrlrange="-87 87"/> 
        <motor name="torque_2" joint="panda_joint2" class="panda" forcerange="-87 87" ctrlrange="-87 87"/> 
        <motor name="torque_3" joint="panda_joint3" class="panda" forcerange="-87 87" ctrlrange="-87 87"/> 
        <motor name="torque_4" joint="panda_joint4" class="panda" forcerange="-87 87" ctrlrange="-87 87"/> 
        <motor name="torque_5" joint="panda_joint5" class="panda" forcerange="-12 12" ctrlrange="-12 12"/> 
        <motor name="torque_6" joint="panda_joint6" class="panda" forcerange="-12 12" ctrlrange="-12 12"/> 
        <motor name="torque_7" joint="panda_joint7" class="panda" forcerange="-12 12" ctrlrange="-12 12"/>  -->
        <!-- <motor name="gripper_direct_actuator_1" joint="panda_finger_joint1" class="panda_finger" forcerange="-70 70" ctrlrange="-70 70"/>
        <motor name="gripper_direct_actuator_2" joint="panda_finger_joint2" class="panda_finger" forcerange="-70 70" ctrlrange="-70 70"/> -->
        <position name="gripper_pos_actuator_1" joint="panda_finger_joint1" class="panda_finger" kp="500" forcerange="-70 70" ctrlrange="0 0.04"/>
        <position name="gripper_pos_actuator_2" joint="panda_finger_joint2" class="panda_finger" kp="500" forcerange="-70 70" ctrlrange="0 0.04"/>
    </actuator>

    <sensor>
        <force name="ee_force_sensor" site="ee_site"/>
        <torque name="ee_torque_sensor" site="ee_site"/>
    </sensor>

</mujoco>
